<?xml version="1.0"?>
	<robot name="imr_arm">
		<!-- The gazebo plugin must stay inside of the robot model-->
		<gazebo>
	    	<plugin name="gazebo_ros_control" filename="libgazebo_ros_control.so">
	      		<robotNamespace>/imr_arm</robotNamespace>
	    	</plugin>
  		</gazebo>
		<link name="world"/>
		<link name="X5-9">
			<inertial>
				<origin rpy="0 0 0" xyz="0 0 0" />
				<mass value="0.35" />
				<inertia ixx="0.01" ixy="0.0" ixz="0.0" iyy="0.01" iyz="0.0" izz="0.01"/>
			</inertial>
			<visual>
				<origin rpy="0 0 0" xyz="0 0 0" />
				<geometry>
					 <mesh filename="package://imr_arm_description/meshes/X5-9.dae"/>
				</geometry>
			</visual>
<!-- 			<collision>
				<origin rpy="0 0 0" xyz="0 0 0" />
				<geometry>
					<box size="0.1 0.1 0.001"/>
				</geometry>
			</collision> -->
		</link>
		<link name="base">
			<inertial>
				<origin rpy="0 0 0" xyz="-0.005 0.016 0.044" />
				<mass value="0.6216" />
				<inertia ixx="0.00528" ixy="0.000041" ixz="-0.000036" iyy="0.000743" iyz="0.000021" izz="0.000516"/>
			</inertial>
			<visual>
				<origin rpy="0 0 0" xyz="0 0 0" />
				<geometry>
					 <mesh filename="package://imr_arm_description/meshes/base_assembly.dae"/>
				</geometry>
			</visual>
<!-- 			<collision>
				<origin rpy="0 0 0" xyz="0 0 0" />
				<geometry>
					<box size="0.01 0.01 0.01"/>
				</geometry>
			</collision> -->
		</link>
		<link name="link1">
			<origin rpy="0 0 0" xyz="0 0.001 0.212" />
			<inertial>
				<origin rpy="0 0 0" xyz="0 0 0" />
				<mass value="0.6616" />
				<inertia ixx="0.006440" ixy="0.000006" ixz="0.000007" iyy="0.006426" iyz="0.000596" izz="0.000393"/>
			</inertial>
			<visual>
				<origin rpy="0 0 0" xyz="0 0 0" />
				<geometry>
					 <mesh filename="package://imr_arm_description/meshes/link1_assembly.dae"/>
				</geometry>
			</visual>
<!-- 			<collision>
				<origin rpy="0 0 0" xyz="0 0 0" />
				<geometry>
					<box size="0.01 0.01 0.01"/>
				</geometry>
			</collision> -->
		</link>
		 <link name="link2">
			<inertial>
				<origin rpy="0 0 0" xyz="-0.001 0 0.210" />
				<mass value="6.6416" />
				<inertia ixx="0.006348" ixy="0.000006" ixz="-0.000008" iyy="0.006331" iyz="-0.000585" izz="0.000385" />
			</inertial>
			<visual>
				<origin rpy="0 0 0" xyz="0 0 0" />
				<geometry>
					 <mesh filename="package://imr_arm_description/meshes/link2_assembly.dae"/>
				</geometry>
			</visual>
		 <!-- <collision>
				<origin rpy="0 0 0" xyz="0 0 0" />
				<geometry>
					<box size="0.1 0.1 0.001"/>
				</geometry>
			</collision>-->
		</link>
		 <link name="wrist">
			<inertial>
				<origin rpy="0 0 0" xyz="0.010 -0.035 0.050" />
				<mass value="0.4014" />
				<inertia ixx="0.000311" ixy="-0.000138" ixz="0.000028" iyy="-0.000383" iyz="-0.000063" izz="0.000941"/>
			</inertial>
			<visual>
				<origin rpy="0 0 0" xyz="0 0 0" />
				<geometry>
					 <mesh filename="package://imr_arm_description/meshes/wrist_assembly.dae"/>
				</geometry>
			</visual>
		 <!-- <collision>
				<origin rpy="0 0 0" xyz="0 0 0" />
				<geometry>
					<box size="0.1 0.1 0.001"/>
				</geometry>
			</collision>-->
		</link>

		
		<joint name="world_to_X5-9" type="fixed">
			<parent link="world"/>
			<child link="X5-9"/>
			<origin xyz="0 0 0"/>
		</joint>

		<joint name="Joint1" type="revolute">
			<origin rpy="0 0 0" xyz="0 0 0.031"/>
			<axis xyz="0 0 1"/>
			<parent link="X5-9"/>
			<child link="base"/>
			<limit lower="-2.6" upper="2.6" effort="9.0" velocity="1.5"/>
			<<dynamics damping="11.0" friction="0.0"/>
		</joint>
		
		<joint name="Joint2" type="revolute">
			<origin rpy="0 0 0" xyz="0 -0.006 0.055"/>
			<axis xyz="0 1 0"/>
			<parent link="base"/>
			<child link="link1"/>
			<limit lower="-3.14" upper="3.14" effort="9.0" velocity="1.5"/>
			<dynamics damping="11.0" friction="0.0"/>
		</joint>

		<joint name="Joint3" type="revolute">
			<origin rpy="0 0 0" xyz="0 0.031 0.280"/>
			<axis xyz="0 1 0"/>
			<parent link="link1"/>
			<child link="link2"/>
			<limit lower="-6.4" upper="6.6" effort="9.0" velocity="1.5"/>
			<dynamics damping="10.0" friction="0.0"/>
		</joint>
		<joint name="Joint4" type="revolute">
			<origin rpy="0 0 0" xyz="0 -0.031 0.280"/>
			<axis xyz="0 1 0"/>
			<parent link="link2"/>
			<child link="wrist"/>
			<limit effort="9.0" velocity="1.5"/>
			<dynamics damping="9.0" friction="0.0"/>
		</joint>
	
		<transmission name="Joint1_Trans">
			<type>transmission_interface/SimpleTransmission</type>
			<joint name="Joint1">
				<!-- EfforJointInterface must reside both in joint and in actuator-->
				<hardwareInterface>EffortJointInterface</hardwareInterface>
			</joint>
			<actuator name="Joint1_X5-9">
				<mechanicalReduction>1</mechanicalReduction>
				<hardwareInterface>EffortJointInterface</hardwareInterface>
			</actuator>
		</transmission>

		<transmission name="Joint2_Trans">
			<type>transmission_interface/SimpleTransmission</type>
			<joint name="Joint2">
				<!-- EfforJointInterface must reside both in joint and in actuator-->
				<hardwareInterface>EffortJointInterface</hardwareInterface>
			</joint>
			<actuator name="Joint2_X5-9">
				<mechanicalReduction>1</mechanicalReduction>
				<hardwareInterface>EffortJointInterface</hardwareInterface>
			</actuator>
		</transmission>

		<transmission name="Joint3_Trans">
			<!-- EfforJointInterface must reside both in joint and in actuator-->
			<type>transmission_interface/SimpleTransmission</type>
			<joint name="Joint3">
				<hardwareInterface>EffortJointInterface</hardwareInterface>
			</joint>
			<actuator name="Joint3_X5-9">
				<mechanicalReduction>1</mechanicalReduction>
				<hardwareInterface>EffortJointInterface</hardwareInterface>
			</actuator>
		</transmission>

		<transmission name="Joint4_Trans">
			<type>transmission_interface/SimpleTransmission</type>
			<joint name="Joint4">
				<!-- EfforJointInterface must reside both in joint and in actuator-->
				<hardwareInterface>EffortJointInterface</hardwareInterface>
			</joint>
			<actuator name="Joint4_X5-4">
				<mechanicalReduction>1</mechanicalReduction>
				<hardwareInterface>EffortJointInterface</hardwareInterface>
			</actuator>
		</transmission>

		<gazebo reference="X5-9">
			<material>Gazebo/Grey</material>
		</gazebo>
		<gazebo reference="base">
			<material>Gazebo/Grey</material>
		</gazebo>
		<gazebo reference="link1">
			<material>Gazebo/Grey</material>
		</gazebo>
		<gazebo reference="link2">
			<material>Gazebo/Grey</material>
		</gazebo>
		<gazebo reference="wrist">
			<material>Gazebo/Grey</material>
		</gazebo>
	</robot>
